<?xml version="1.0"?>
<sdf version='1.6'>
  <world name='default'>
    <light name='sun' type='directional'>
      <cast_shadows>1</cast_shadows>
      <pose frame=''>0 0 10 0 -0 0</pose>
      <diffuse>0.8 0.8 0.8 1</diffuse>
      <specular>0.1 0.1 0.1 1</specular>
      <attenuation>
        <range>1000</range>
        <constant>0.9</constant>
        <linear>0.01</linear>
        <quadratic>0.001</quadratic>
      </attenuation>
      <direction>-0.5 0.5 -1</direction>
    </light>
    <model name='ground_plane'>
      <static>1</static>
      <link name='link'>
        <collision name='collision'>
          <geometry>
            <plane>
              <normal>0 0 1</normal>
              <size>100 100</size>
            </plane>
          </geometry>
          <surface>
            <friction>
              <ode>
                <mu>100</mu>
                <mu2>50</mu2>
              </ode>
              <torsional>
                <ode/>
              </torsional>
            </friction>
            <contact>
              <ode/>
            </contact>
            <bounce/>
          </surface>
          <max_contacts>10</max_contacts>
        </collision>
        <visual name='visual'>
          <cast_shadows>0</cast_shadows>
          <geometry>
            <plane>
              <normal>0 0 1</normal>
              <size>100 100</size>
            </plane>
          </geometry>
          <material>
            <script>
              <uri>file://media/materials/scripts/gazebo.material</uri>
              <name>Gazebo/Grey</name>
            </script>
          </material>
        </visual>
        <self_collide>0</self_collide>
        <kinematic>0</kinematic>
        <gravity>1</gravity>
      </link>
    </model>

    <physics name='default_physics' default='0' type='ode'>
      <ode>
        <solver>
          <type>quick</type>
          <iters>10</iters>
          <sor>1.3</sor>
          <use_dynamic_moi_rescaling>0</use_dynamic_moi_rescaling>
        </solver>
        <constraints>
          <cfm>0</cfm>
          <erp>0.2</erp>
          <contact_max_correcting_vel>100</contact_max_correcting_vel>
          <contact_surface_layer>0.001</contact_surface_layer>
        </constraints>
      </ode>
      <max_step_size>0.001</max_step_size>
      <real_time_factor>1</real_time_factor>
      <real_time_update_rate>500</real_time_update_rate>
    </physics>

	  <model name='robot'>
		<link name='base_link'>
		  <inertial>
		    <pose>0.065 0 0.0625 0 -0 0</pose>
		    <mass>0.6</mass>
		    <inertia>
		      <ixx>0.00525625</ixx>
		      <ixy>0</ixy>
		      <ixz>0.0005625</ixz>
		      <iyy>0.00593125</iyy>
		      <iyz>0</iyz>
		      <izz>0.008275</izz>
		    </inertia>
		  </inertial>
		  <collision name='base_link_fixed_joint_lump__chassis_collision'>
		    <pose>0.05 0 0.075 0 -0 0</pose>
		    <geometry>
		      <box>
		        <size>0.3 0.3 0.15</size>
		      </box>
		    </geometry>
		    <surface>
		      <contact>
		        <ode/>
		      </contact>
		      <friction>
		        <ode/>
		      </friction>
		    </surface>
		  </collision>
		  <collision name='base_link_fixed_joint_lump__caster_wheel_collision_1'>
		    <pose>0.14 0 0 0 -0 0</pose>
		    <geometry>
		      <sphere>
		        <radius>0.05</radius>
		      </sphere>
		    </geometry>
		    <surface>
		      <contact>
		        <ode/>
		      </contact>
		      <friction>
		        <ode>
		          <mu>0.001</mu>
		          <mu2>0.001</mu2>
		        </ode>
		      </friction>
		    </surface>
		  </collision>
		  <visual name='base_link_fixed_joint_lump__chassis_visual'>
		    <pose>0.05 0 0.075 0 -0 0</pose>
		    <geometry>
		      <box>
		        <size>0.3 0.3 0.15</size>
		      </box>
		    </geometry>
		    <material>
		      <script>
		        <name>Gazebo/White</name>
		        <uri>file://media/materials/scripts/gazebo.material</uri>
		      </script>
		    </material>
		  </visual>
		  <visual name='base_link_fixed_joint_lump__caster_wheel_visual_1'>
		    <pose>0.14 0 0 0 -0 0</pose>
		    <geometry>
		      <sphere>
		        <radius>0.05</radius>
		      </sphere>
		    </geometry>
		    <material>
		      <script>
		        <name>Gazebo/Black</name>
		        <uri>file://media/materials/scripts/gazebo.material</uri>
		      </script>
		    </material>
		  </visual>
		</link>
		<joint name='left_wheel_joint' type='revolute'>
		  <pose relative_to='base_link'>0 0.175 0 -1.5708 0 0</pose>
		  <parent>base_link</parent>
		  <child>left_wheel</child>
		  <axis>
		    <xyz>0 0 1</xyz>
		    <limit>
		      <lower>-1e+16</lower>
		      <upper>1e+16</upper>
		    </limit>
		    <dynamics>
		      <spring_reference>0</spring_reference>
		      <spring_stiffness>0</spring_stiffness>
		    </dynamics>
		  </axis>
		</joint>
		<link name='left_wheel'>
		  <pose relative_to='left_wheel_joint'>0 0 0 0 -0 0</pose>
		  <inertial>
		    <pose>0 0 0 0 -0 0</pose>
		    <mass>0.1</mass>
		    <inertia>
		      <ixx>7.58333e-05</ixx>
		      <ixy>0</ixy>
		      <ixz>0</ixz>
		      <iyy>7.58333e-05</iyy>
		      <iyz>0</iyz>
		      <izz>0.000125</izz>
		    </inertia>
		  </inertial>
		  <collision name='left_wheel_collision'>
		    <pose>0 0 0 0 -0 0</pose>
		    <geometry>
		      <cylinder>
		        <length>0.04</length>
		        <radius>0.05</radius>
		      </cylinder>
		    </geometry>
		    <surface>
		      <contact>
		        <ode/>
		      </contact>
		      <friction>
		        <ode/>
		      </friction>
		    </surface>
		  </collision>
		  <visual name='left_wheel_visual'>
		    <pose>0 0 0 0 -0 0</pose>
		    <geometry>
		      <cylinder>
		        <length>0.04</length>
		        <radius>0.05</radius>
		      </cylinder>
		    </geometry>
		    <material>
		      <script>
		        <name>Gazebo/Blue</name>
		        <uri>file://media/materials/scripts/gazebo.material</uri>
		      </script>
		    </material>
		  </visual>
		</link>
		<joint name='right_wheel_joint' type='revolute'>
		  <pose relative_to='base_link'>0 -0.175 0 1.5708 -0 0</pose>
		  <parent>base_link</parent>
		  <child>right_wheel</child>
		  <axis>
		    <xyz>0 0 -1</xyz>
		    <limit>
		      <lower>-1e+16</lower>
		      <upper>1e+16</upper>
		    </limit>
		    <dynamics>
		      <spring_reference>0</spring_reference>
		      <spring_stiffness>0</spring_stiffness>
		    </dynamics>
		  </axis>
		</joint>
		<link name='right_wheel'>
		  <pose relative_to='right_wheel_joint'>0 0 0 0 -0 0</pose>
		  <inertial>
		    <pose>0 0 0 0 -0 0</pose>
		    <mass>0.1</mass>
		    <inertia>
		      <ixx>7.58333e-05</ixx>
		      <ixy>0</ixy>
		      <ixz>0</ixz>
		      <iyy>7.58333e-05</iyy>
		      <iyz>0</iyz>
		      <izz>0.000125</izz>
		    </inertia>
		  </inertial>
		  <collision name='right_wheel_collision'>
		    <pose>0 0 0 0 -0 0</pose>
		    <geometry>
		      <cylinder>
		        <length>0.04</length>
		        <radius>0.05</radius>
		      </cylinder>
		    </geometry>
		    <surface>
		      <contact>
		        <ode/>
		      </contact>
		      <friction>
		        <ode/>
		      </friction>
		    </surface>
		  </collision>
		  <visual name='right_wheel_visual'>
		    <pose>0 0 0 0 -0 0</pose>
		    <geometry>
		      <cylinder>
		        <length>0.04</length>
		        <radius>0.05</radius>
		      </cylinder>
		    </geometry>
		    <material>
		      <script>
		        <name>Gazebo/Blue</name>
		        <uri>file://media/materials/scripts/gazebo.material</uri>
		      </script>
		    </material>
		  </visual>
		</link>
	  </model>
	  
    <plugin name="GazeboPlugin" filename="lib/libGazeboCoSimPlugin.so"><portNumber>14581</portNumber></plugin>
  </world>
</sdf>
